<?xml version="1.0" ?>
<!-- =================================================================================== -->
<!-- |    This document was autogenerated by xacro from /home/mingq/workspace/ros2/erp42_ros/src/erp42_description/urdf/erp42.xacro | -->
<!-- |    EDITING THIS FILE BY HAND IS NOT RECOMMENDED                                 | -->
<!-- =================================================================================== -->
<robot name="erp42">
  <!-- ======================================== Variables ======================================== -->
  <!-- ======================================== Links ======================================== -->
  <!-- Base Footprint -->
  <link name="base_footprint"/>
  <!-- Base link -->
  <link name="base_link">
    <!-- Inertia -->
    <inertial>
      <mass value="160"/>
      <origin rpy="0 0 0" xyz="0 0 0"/>
      <inertia ixx="20.43" ixy="0.584" ixz="-0.191" iyy="54.197" iyz="-0.2449" izz="72.2588"/>
    </inertial>
    <!-- Chassis -->
    <collision>
      <origin rpy="0 0 0" xyz="0.02 0 0"/>
      <geometry>
        <box size="1.580 0.950 0.316"/>
      </geometry>
    </collision>
    <visual>
      <origin rpy="0 0 0" xyz="0 0 0"/>
      <geometry>
        <mesh filename="file:///home/mingq/workspace/ros2/erp42_ros/install/erp42_description/share/erp42_description/meshes/erp42_chassis.dae" scale="0.001 0.001 0.001"/>
      </geometry>
    </visual>
    <!-- Front bumper -->
    <collision>
      <origin rpy="0 0 0" xyz="0.9199999999999999 0 -0.075"/>
      <geometry>
        <box size="0.22 1.0 0.15"/>
      </geometry>
    </collision>
    <visual>
      <origin rpy="0 0 0" xyz="0.9199999999999999 0 -0.075"/>
      <geometry>
        <mesh filename="file:///home/mingq/workspace/ros2/erp42_ros/install/erp42_description/share/erp42_description/meshes/erp42_bumper.dae" scale="0.001 0.001 0.001"/>
      </geometry>
    </visual>
    <!-- Rear bumper -->
    <collision>
      <origin rpy="0 0 3.14159" xyz="-0.88 0 -0.075"/>
      <geometry>
        <box size="0.22 1.0 0.15"/>
      </geometry>
    </collision>
    <visual>
      <origin rpy="0 0 3.14159" xyz="-0.88 0 -0.075"/>
      <geometry>
        <mesh filename="file:///home/mingq/workspace/ros2/erp42_ros/install/erp42_description/share/erp42_description/meshes/erp42_bumper.dae" scale="0.001 0.001 0.001"/>
      </geometry>
    </visual>
  </link>
  <!-- Steering assemblies -->
  <link name="front_left_steering_hub">
    <!-- Inertia -->
    <inertial>
      <mass value="0.1"/>
      <origin rpy="0 0 0" xyz="0 0 0"/>
      <inertia ixx="0.001" ixy="0.0" ixz="0.0" iyy="0.001" iyz="0.0" izz="0.001"/>
    </inertial>
  </link>
  <link name="front_right_steering_hub">
    <!-- Inertia -->
    <inertial>
      <mass value="0.1"/>
      <origin rpy="0 0 0" xyz="0 0 0"/>
      <inertia ixx="0.001" ixy="0.0" ixz="0.0" iyy="0.001" iyz="0.0" izz="0.001"/>
    </inertial>
  </link>
  <link name="front_left_wheel">
    <!-- Inertia -->
    <inertial>
      <mass value="7.0"/>
      <origin xyz="0 0 0"/>
      <inertia ixx="0.145425" ixy="0.0" ixz="0.0" iyy="0.25515" iyz="0.0" izz="0.145425"/>
    </inertial>
    <!-- Collision -->
    <collision>
      <origin rpy="-1.570795 0 0" xyz="0 0 0"/>
      <geometry>
        <cylinder length="0.175" radius="0.27"/>
      </geometry>
    </collision>
    <!-- Mesh files -->
    <visual>
      <origin rpy="0 0 0" xyz="0 0 0"/>
      <geometry>
        <mesh filename="file:///home/mingq/workspace/ros2/erp42_ros/install/erp42_description/share/erp42_description/meshes/erp42_tire.dae" scale="0.001 0.001 0.001"/>
      </geometry>
    </visual>
    <visual>
      <origin rpy="0 0 0" xyz="0 0 0"/>
      <geometry>
        <mesh filename="file:///home/mingq/workspace/ros2/erp42_ros/install/erp42_description/share/erp42_description/meshes/erp42_rim.dae" scale="0.001 0.001 0.001"/>
      </geometry>
    </visual>
  </link>
  <link name="front_right_wheel">
    <!-- Inertia -->
    <inertial>
      <mass value="7.0"/>
      <origin xyz="0 0 0"/>
      <inertia ixx="0.145425" ixy="0.0" ixz="0.0" iyy="0.25515" iyz="0.0" izz="0.145425"/>
    </inertial>
    <!-- Collision -->
    <collision>
      <origin rpy="-1.570795 0 0" xyz="0 0 0"/>
      <geometry>
        <cylinder length="0.175" radius="0.27"/>
      </geometry>
    </collision>
    <!-- Mesh files -->
    <visual>
      <origin rpy="0 0 0" xyz="0 0 0"/>
      <geometry>
        <mesh filename="file:///home/mingq/workspace/ros2/erp42_ros/install/erp42_description/share/erp42_description/meshes/erp42_tire.dae" scale="0.001 0.001 0.001"/>
      </geometry>
    </visual>
    <visual>
      <origin rpy="0 0 0" xyz="0 0 0"/>
      <geometry>
        <mesh filename="file:///home/mingq/workspace/ros2/erp42_ros/install/erp42_description/share/erp42_description/meshes/erp42_rim.dae" scale="0.001 0.001 0.001"/>
      </geometry>
    </visual>
  </link>
  <link name="rear_left_wheel">
    <!-- Inertia -->
    <inertial>
      <mass value="7.0"/>
      <origin xyz="0 0 0"/>
      <inertia ixx="0.145425" ixy="0.0" ixz="0.0" iyy="0.25515" iyz="0.0" izz="0.145425"/>
    </inertial>
    <!-- Collision -->
    <collision>
      <origin rpy="-1.570795 0 0" xyz="0 0 0"/>
      <geometry>
        <cylinder length="0.175" radius="0.27"/>
      </geometry>
    </collision>
    <!-- Mesh files -->
    <visual>
      <origin rpy="0 0 0" xyz="0 0 0"/>
      <geometry>
        <mesh filename="file:///home/mingq/workspace/ros2/erp42_ros/install/erp42_description/share/erp42_description/meshes/erp42_tire.dae" scale="0.001 0.001 0.001"/>
      </geometry>
    </visual>
    <visual>
      <origin rpy="0 0 0" xyz="0 0 0"/>
      <geometry>
        <mesh filename="file:///home/mingq/workspace/ros2/erp42_ros/install/erp42_description/share/erp42_description/meshes/erp42_rim.dae" scale="0.001 0.001 0.001"/>
      </geometry>
    </visual>
  </link>
  <link name="rear_right_wheel">
    <!-- Inertia -->
    <inertial>
      <mass value="7.0"/>
      <origin xyz="0 0 0"/>
      <inertia ixx="0.145425" ixy="0.0" ixz="0.0" iyy="0.25515" iyz="0.0" izz="0.145425"/>
    </inertial>
    <!-- Collision -->
    <collision>
      <origin rpy="-1.570795 0 0" xyz="0 0 0"/>
      <geometry>
        <cylinder length="0.175" radius="0.27"/>
      </geometry>
    </collision>
    <!-- Mesh files -->
    <visual>
      <origin rpy="0 0 0" xyz="0 0 0"/>
      <geometry>
        <mesh filename="file:///home/mingq/workspace/ros2/erp42_ros/install/erp42_description/share/erp42_description/meshes/erp42_tire.dae" scale="0.001 0.001 0.001"/>
      </geometry>
    </visual>
    <visual>
      <origin rpy="0 0 0" xyz="0 0 0"/>
      <geometry>
        <mesh filename="file:///home/mingq/workspace/ros2/erp42_ros/install/erp42_description/share/erp42_description/meshes/erp42_rim.dae" scale="0.001 0.001 0.001"/>
      </geometry>
    </visual>
  </link>
  <!-- ======================================== Joints ======================================== -->
  <!-- base_footprint to base_link -->
  <joint name="base_link_joint" type="fixed">
    <origin rpy="0 0 0" xyz="0 0 0.27"/>
    <parent link="base_footprint"/>
    <child link="base_link"/>
  </joint>
  <!-- base_link to front_left_steering_hub -->
  <joint name="front_left_steering_hub_joint" type="revolute">
    <origin rpy="0 0 0" xyz="0.52 0.4925 0"/>
    <parent link="base_link"/>
    <child link="front_left_steering_hub"/>
    <axis xyz="0 0 1"/>
    <limit effort="100" lower="-0.698132" upper="0.698132" velocity="100"/>
    <dynamics damping="0.1" friction="0.1"/>
  </joint>
  <!-- base_link to front_right_steering_hub -->
  <joint name="front_right_steering_hub_joint" type="revolute">
    <origin rpy="0 0 0" xyz="0.52 -0.4925 0"/>
    <parent link="base_link"/>
    <child link="front_right_steering_hub"/>
    <axis xyz="0 0 1"/>
    <limit effort="100" lower="-0.698132" upper="0.698132" velocity="100"/>
    <dynamics damping="0.1" friction="0.1"/>
  </joint>
  <!-- front_left_steering_hub to front_right_wheel -->
  <joint name="front_left_wheel_joint" type="continuous">
    <origin rpy="0 0 0" xyz="0 0 0"/>
    <parent link="front_left_steering_hub"/>
    <child link="front_left_wheel"/>
    <axis xyz="0 1 0"/>
  </joint>
  <!-- front_right_steering_hub to front_right_wheel -->
  <joint name="front_right_wheel_joint" type="continuous">
    <origin rpy="3.14159 0 0" xyz="0 0 0"/>
    <parent link="front_right_steering_hub"/>
    <child link="front_right_wheel"/>
    <axis xyz="0 -1 0"/>
  </joint>
  <!-- base_link to rear_left_wheel -->
  <joint name="rear_left_wheel_joint" type="continuous">
    <origin rpy="0 0 0" xyz="-0.52 0.4925 0"/>
    <parent link="base_link"/>
    <child link="rear_left_wheel"/>
    <axis xyz="0 1 0"/>
  </joint>
  <!-- base_link to rear_right_wheel -->
  <joint name="rear_right_wheel_joint" type="continuous">
    <origin rpy="3.14159 0 0" xyz="-0.52 -0.4925 0"/>
    <parent link="base_link"/>
    <child link="rear_right_wheel"/>
    <axis xyz="0 -1 0"/>
  </joint>
</robot>
